<?xml version="1.0" ?>
<robot name="rrbot" xmlns:xacro="http://www.ros.org/wiki/xacro">

  <xacro:include filename="$(find rrbot_description)/urdf/rrbot.gazebo" />
  <xacro:include filename="$(find rrbot_description)/urdf/materials.xacro"/>

  <!--link name="world"/>
  <gazebo reference="world">
    <gravity>0</gravity>
  </gazebo>

  <joint name="world_joint" type="floating">
    <origin xyz="0 0 0" rpy="0 0 0"/>
    <parent link="world"/>
    <child link="rrbot__link_0"/>
  </joint-->


  <joint name="rrbot__link_0_0_JOINT_2" type="fixed">
    <parent link="rrbot__link_0_0"/>
    <child link="rrbot__link_2_clone_1_clone"/>
    <origin rpy="0       0.54898  0" xyz="-0.03899  0.00105 -0.02898"/>
    <axis xyz="0  0  0"/>
    <limit effort="0" lower="0" upper="0" velocity="0"/>
  </joint>
  <joint name="rrbot__link_0_0_clone_0_JOINT_10" type="fixed">
    <parent link="rrbot__link_0_0_clone_0"/>
    <child link="rrbot__link_2_clone_1_clone_0_clone"/>
    <origin rpy="-4.00000000e-05  -5.49010000e-01   5.00000000e-05" xyz="-0.039    0       0.02898"/>
    <axis xyz="0  0  0"/>
    <limit effort="0" lower="0" upper="0" velocity="0"/>
  </joint>
  <joint name="rrbot__link_0_0_clone_1_JOINT_4" type="fixed">
    <parent link="rrbot__link_0_0_clone_1"/>
    <child link="rrbot__link_2_clone_1_clone_0"/>
    <origin rpy="-4.00000000e-05  -5.49010000e-01   5.00000000e-05" xyz="0.04077  0      -0.02898"/>
    <axis xyz="0  0  0"/>
    <limit effort="0" lower="0" upper="0" velocity="0"/>
  </joint>
  <joint name="rrbot__link_0_0_clone_JOINT_0" type="fixed">
    <parent link="rrbot__link_0_0_clone"/>
    <child link="rrbot__link_2_clone_1"/>
    <origin rpy="0       0.54898  0" xyz="0.03899  0.00105  0.02899"/>
    <axis xyz="0  0  0"/>
    <limit effort="0" lower="0" upper="0" velocity="0"/>
  </joint>
  <joint name="rrbot__limb_joint_1" type="continuous">
    <parent link="rrbot__link_0_0_clone_clone"/>
    <child link="rrbot__link_0_0_clone_clone_clone"/>
    <origin rpy="3.141592  0  0" xyz="0.00928  0.00016  0"/>
    <axis xyz="-1  0  0"/>

  </joint>
  <joint name="rrbot__limb_joint_2" type="continuous">
    <parent link="rrbot__link_0_0_clone_clone_clone_0"/>
    <child link="rrbot__link_0_0_clone_clone_clone_0_clone"/>
    <origin rpy="0  0  0" xyz="-0.00928  0.00016  0"/>
    <axis xyz="-1  0  0"/>

  </joint>
  <joint name="rrbot__link_0_0_clone_clone_clone_0_clone_JOINT_18" type="fixed">
    <parent link="rrbot__link_0_0_clone_clone_clone_0_clone"/>
    <child link="rrbot__link_0_0"/>
    <origin rpy="0  0  0" xyz="-0.02655 -0.00019  0"/>
    <axis xyz="0  0  0"/>
    <limit effort="0" lower="0" upper="0" velocity="0"/>
  </joint>
  <joint name="rrbot__limb_joint_3" type="continuous">
    <parent link="rrbot__link_0_0_clone_clone_clone_1"/>
    <child link="rrbot__link_0_0_clone_clone_clone_clone"/>
    <origin rpy="0  0  0" xyz="8.98000000e-03   0.00000000e+00   8.00000000e-05"/>
    <axis xyz="-1  0  0"/>

  </joint>
  <joint name="rrbot__limb_joint_4" type="continuous">
    <parent link="rrbot__link_0_0_clone_clone_clone_2"/>
    <child link="rrbot__link_0_0_clone_clone_clone_3"/>
    <origin rpy="3.141592  0  0" xyz="-0.00928  0       0"/>
    <axis xyz="-1  0  0"/>

  </joint>
  <joint name="rrbot__link_0_0_clone_clone_clone_3_JOINT_22" type="fixed">
    <parent link="rrbot__link_0_0_clone_clone_clone_3"/>
    <child link="rrbot__link_0_0_clone_0"/>
    <origin rpy="3.00000000e-05   2.00000000e-05  -3.00000000e-05" xyz="-0.02655  0       0"/>
    <axis xyz="0  0  0"/>
    <limit effort="0" lower="0" upper="0" velocity="0"/>
  </joint>
  <joint name="rrbot__link_0_0_clone_clone_clone_JOINT_16" type="fixed">
    <parent link="rrbot__link_0_0_clone_clone_clone"/>
    <child link="rrbot__link_0_0_clone"/>
    <origin rpy="0  0  0" xyz="0.02655 -0.00019  0"/>
    <axis xyz="0  0  0"/>
    <limit effort="0" lower="0" upper="0" velocity="0"/>
  </joint>
  <joint name="rrbot__link_0_0_clone_clone_clone_clone_JOINT_20" type="fixed">
    <parent link="rrbot__link_0_0_clone_clone_clone_clone"/>
    <child link="rrbot__link_0_0_clone_1"/>
    <origin rpy="3.00000000e-05   2.00000000e-05  -3.00000000e-05" xyz="2.71700000e-02   0.00000000e+00  -8.00000000e-05"/>
    <axis xyz="0  0  0"/>
    <limit effort="0" lower="0" upper="0" velocity="0"/>
  </joint>
  <joint name="rrbot__link_0_JOINT_0_0" type="fixed">
    <parent link="rrbot__link_0"/>
    <child link="rrbot__link_3"/>
    <origin rpy="1.00000000e-05   1.00000000e-05  -1.00000000e-05" xyz="-0.05636  0.86928  0.349901"/>
    <axis xyz="0  0  0"/>
    <limit effort="0" lower="0" upper="0" velocity="0"/>
  </joint>
  <joint name="rrbot__link_0_JOINT_0" type="fixed">
    <parent link="rrbot__link_0"/>
    <child link="rrbot__link_0_clone"/>
    <origin rpy="0  0  0" xyz="-4.00000000e-05   6.77990000e-01   0.273561"/>
    <axis xyz="0  0  0"/>
    <limit effort="0" lower="0" upper="0" velocity="0"/>
  </joint>
  <joint name="rrbot__link_0_JOINT_1" type="fixed">
    <parent link="rrbot__link_0"/>
    <child link="rrbot__link_3_clone"/>
    <origin rpy="3.00000000e-05   2.00000000e-05  -3.00000000e-05" xyz="0.05636  0.86928  0.349901"/>
    <axis xyz="0  0  0"/>
    <limit effort="0" lower="0" upper="0" velocity="0"/>
  </joint>
  <joint name="rrbot__link_0_clone_0_JOINT_2_0" type="fixed">
    <parent link="rrbot__link_0_clone_0"/>
    <child link="rrbot__link_0_clone_6_clone_0"/>
    <origin rpy="0       0      -0.00248" xyz="0      -0.09086  0"/>
    <axis xyz="0  0  0"/>
    <limit effort="0" lower="0" upper="0" velocity="0"/>
  </joint>
  <joint name="rrbot__link_0_clone_1_JOINT_4" type="fixed">
    <parent link="rrbot__link_0_clone_1"/>
    <child link="rrbot__link_0_clone_6_clone_2"/>
    <origin rpy="0       0      -0.00248" xyz="0      -0.09257  0"/>
    <axis xyz="0  0  0"/>
    <limit effort="0" lower="0" upper="0" velocity="0"/>
  </joint>
  <joint name="rrbot__link_0_clone_2_JOINT_8" type="fixed">
    <parent link="rrbot__link_0_clone_2"/>
    <child link="rrbot__link_0_clone_clone"/>
    <origin rpy="1.00000000e-05   1.00000000e-05  -1.00000000e-05" xyz="0      -0.13431  0"/>
    <axis xyz="0  0  0"/>
    <limit effort="0" lower="0" upper="0" velocity="0"/>
  </joint>
  <joint name="rrbot__link_0_clone_3_JOINT_9" type="fixed">
    <parent link="rrbot__link_0_clone_3"/>
    <child link="rrbot__link_0_clone_6_clone_6"/>
    <origin rpy="0       0      -0.00248" xyz="0      -0.09278  0"/>
    <axis xyz="0  0  0"/>
    <limit effort="0" lower="0" upper="0" velocity="0"/>
  </joint>
  <joint name="rrbot__link_0_clone_4_JOINT_11" type="fixed">
    <parent link="rrbot__link_0_clone_4"/>
    <child link="rrbot__link_0_clone_6_clone_8"/>
    <origin rpy="0       0      -0.00248" xyz="0     -0.0927  0"/>
    <axis xyz="0  0  0"/>
    <limit effort="0" lower="0" upper="0" velocity="0"/>
  </joint>
  <joint name="rrbot__body_joint_1" type="revolute">
    <parent link="rrbot__link_0_clone_6"/>
    <child link="rrbot__link_0_clone_6_clone"/>
    <origin rpy="0       0      0" xyz="-2.00000000e-05  -1.70600000e-02   0.00000000e+00"/>
    <axis xyz="0  0  1"/>
    <limit effort="2.0" lower="-0.4" upper="0.4" velocity="1.0"/>
  </joint>
  <joint name="rrbot__body_joint_2" type="revolute">
    <parent link="rrbot__link_0_clone_6_clone_0"/>
    <child link="rrbot__link_0_clone_6_clone_1"/>
    <origin rpy="0  0  0" xyz="4.00000000e-05  -1.79300000e-02   0.00000000e+00"/>
    <axis xyz="0  0  1"/>
    <limit effort="2.0" lower="-0.4" upper="0.4" velocity="1.0"/>
  </joint>
  <joint name="rrbot__link_0_clone_6_clone_1_JOINT_3" type="fixed">
    <parent link="rrbot__link_0_clone_6_clone_1"/>
    <child link="rrbot__link_0_clone_1"/>
    <origin rpy="0       0       0.00248" xyz="0.00023 -0.0925   0"/>
    <axis xyz="0  0  0"/>
    <limit effort="0" lower="0" upper="0" velocity="0"/>
  </joint>
  <joint name="rrbot__body_joint_3" type="revolute">
    <parent link="rrbot__link_0_clone_6_clone_2"/>
    <child link="rrbot__link_0_clone_6_clone_3"/>
    <origin rpy="0  0  0" xyz="4.00000000e-05  -1.81600000e-02   0.00000000e+00"/>
    <axis xyz="0  0  1"/>
    <limit effort="2.0" lower="-0.4" upper="0.4" velocity="1.0"/>
  </joint>
  <joint name="rrbot__link_0_clone_6_clone_3_JOINT_6" type="fixed">
    <parent link="rrbot__link_0_clone_6_clone_3"/>
    <child link="rrbot__link_0_clone_2"/>
    <origin rpy="0       0       0.00248" xyz="0.00022 -0.0922   0"/>
    <axis xyz="0  0  0"/>
    <limit effort="0" lower="0" upper="0" velocity="0"/>
  </joint>
  <joint name="rrbot__body_joint_4" type="revolute">
    <parent link="rrbot__link_0_clone_6_clone_4"/>
    <child link="rrbot__link_0_clone_6_clone_5"/>
    <origin rpy="0  0  0" xyz="3.00000000e-05  -1.57100000e-02   0.00000000e+00"/>
    <axis xyz="0  0  1"/>
    <limit effort="2.0" lower="-0.523" upper="0.523" velocity="1.0"/>
  </joint>
  <joint name="rrbot__link_0_clone_6_clone_5_JOINT_8" type="fixed">
    <parent link="rrbot__link_0_clone_6_clone_5"/>
    <child link="rrbot__link_0_clone_3"/>
    <origin rpy="0       0       0.00248" xyz="0.00023 -0.0928   0"/>
    <axis xyz="0  0  0"/>
    <limit effort="0" lower="0" upper="0" velocity="0"/>
  </joint>
  <joint name="rrbot__body_joint_5" type="revolute">
    <parent link="rrbot__link_0_clone_6_clone_6"/>
    <child link="rrbot__link_0_clone_6_clone_7"/>
    <origin rpy="0  0  0" xyz="3.00000000e-05  -1.57500000e-02   0.00000000e+00"/>
    <axis xyz="0  0  1"/>
    <limit effort="1.0" lower="-0.523" upper="0.523" velocity="1.0"/>
  </joint>
  <joint name="rrbot__link_0_clone_6_clone_7_JOINT_10" type="fixed">
    <parent link="rrbot__link_0_clone_6_clone_7"/>
    <child link="rrbot__link_0_clone_4"/>
    <origin rpy="0       0       0.00248" xyz="0.00022 -0.09222  0"/>
    <axis xyz="0  0  0"/>
    <limit effort="0" lower="0" upper="0" velocity="0"/>
  </joint>
  <joint name="rrbot__body_joint_6" type="revolute">
    <parent link="rrbot__link_0_clone_6_clone_8"/>
    <child link="rrbot__link_0_clone_6_clone_9"/>
    <origin rpy="0  0  0" xyz="4.00000000e-05  -1.75300000e-02   0.00000000e+00"/>
    <axis xyz="0  0  1"/>
    <limit effort="1.0" lower="-0.523" upper="0.523" velocity="1.0"/>
  </joint>
  <joint name="rrbot__link_0_clone_6_clone_9_JOINT_12" type="fixed">
    <parent link="rrbot__link_0_clone_6_clone_9"/>
    <child link="rrbot__link_0_clone_5"/>
    <origin rpy="0       0       0.00248" xyz="0.00023 -0.09266  0"/>
    <axis xyz="0  0  0"/>
    <limit effort="0" lower="0" upper="0" velocity="0"/>
  </joint>
  <joint name="rrbot__link_0_clone_6_clone_JOINT_1" type="fixed">
    <parent link="rrbot__link_0_clone_6_clone"/>
    <child link="rrbot__link_0_clone_0"/>
    <origin rpy="0       0       0.00248" xyz="-0.00076 -0.09177  0"/>
    <axis xyz="0  0  0"/>
    <limit effort="0" lower="0" upper="0" velocity="0"/>
  </joint>
  <joint name="rrbot__link_0_clone_JOINT_0_0" type="fixed">
    <parent link="rrbot__link_0_clone"/>
    <child link="rrbot__link_0_clone_6"/>
    <origin rpy="0       0      -0.00124" xyz="0.00103 -0.05492  0"/>
    <axis xyz="0  0  0"/>
    <limit effort="0" lower="0" upper="0" velocity="0"/>
  </joint>
  <joint name="rrbot__link_0_clone_JOINT_0" type="fixed">
    <parent link="rrbot__link_0_clone"/>
    <child link="rrbot__link_0_0_clone_clone_clone_0"/>
    <origin rpy="0  0  0" xyz="-0.07139  0.00369  0.00213"/>
    <axis xyz="0  0  0"/>
    <limit effort="0" lower="0" upper="0" velocity="0"/>
  </joint>
  <joint name="rrbot__link_0_clone_JOINT_3" type="fixed">
    <parent link="rrbot__link_0_clone"/>
    <child link="rrbot__link_0_0_clone_clone"/>
    <origin rpy="0  0  0" xyz="0.07148  0.00369  0.00213"/>
    <axis xyz="0  0  0"/>
    <limit effort="0" lower="0" upper="0" velocity="0"/>
  </joint>
  <joint name="rrbot__link_0_clone_clone_JOINT_0" type="fixed">
    <parent link="rrbot__link_0_clone_clone"/>
    <child link="rrbot__link_0_0_clone_clone_clone_2"/>
    <origin rpy="-1.00000000e-05  -1.00000000e-05   1.00000000e-05" xyz="-0.07139  0.00078  0.00212"/>
    <axis xyz="0  0  0"/>
    <limit effort="0" lower="0" upper="0" velocity="0"/>
  </joint>
  <joint name="rrbot__link_0_clone_clone_JOINT_12" type="fixed">
    <parent link="rrbot__link_0_clone_clone"/>
    <child link="rrbot__link_0_0_clone_clone_clone_1"/>
    <origin rpy="-1.00000000e-05  -1.00000000e-05   1.00000000e-05" xyz="0.06938  0.00078  0.00213"/>
    <axis xyz="0  0  0"/>
    <limit effort="0" lower="0" upper="0" velocity="0"/>
  </joint>
  <joint name="rrbot__link_0_clone_clone_JOINT_7" type="fixed">
    <parent link="rrbot__link_0_clone_clone"/>
    <child link="rrbot__link_0_clone_6_clone_4"/>
    <origin rpy="-2.00000000e-05  -1.00000000e-05  -2.46000000e-03" xyz="0      -0.05485  0"/>
    <axis xyz="0  0  0"/>
    <limit effort="0" lower="0" upper="0" velocity="0"/>
  </joint>
  <joint name="rrbot__link_2_clone_1_JOINT_1" type="fixed">
    <parent link="rrbot__link_2_clone_1"/>
    <child link="rrbot__link_2_clone"/>
    <origin rpy="0      -0.54898  0" xyz="-0.00056  0       0.04497"/>
    <axis xyz="0  0  0"/>
    <limit effort="0" lower="0" upper="0" velocity="0"/>
  </joint>
  <joint name="rrbot__link_2_clone_1_clone_0_JOINT_5" type="fixed">
    <parent link="rrbot__link_2_clone_1_clone_0"/>
    <child link="rrbot__link_2_clone_clone_0"/>
    <origin rpy="0       0.54899  0" xyz="-0.00057  0      -0.04497"/>
    <axis xyz="0  0  0"/>
    <limit effort="0" lower="0" upper="0" velocity="0"/>
  </joint>
  <joint name="rrbot__link_2_clone_1_clone_0_clone_JOINT_11" type="fixed">
    <parent link="rrbot__link_2_clone_1_clone_0_clone"/>
    <child link="rrbot__link_2_clone_clone_0_clone"/>
    <origin rpy="0       0.54899  0" xyz="0.00056  0       0.04497"/>
    <axis xyz="0  0  0"/>
    <limit effort="0" lower="0" upper="0" velocity="0"/>
  </joint>
  <joint name="rrbot__link_2_clone_1_clone_JOINT_3" type="fixed">
    <parent link="rrbot__link_2_clone_1_clone"/>
    <child link="rrbot__link_2_clone_clone"/>
    <origin rpy="0      -0.54898  0" xyz="0.00057  0      -0.04497"/>
    <axis xyz="0  0  0"/>
    <limit effort="0" lower="0" upper="0" velocity="0"/>
  </joint>

  <link name="rrbot__link_0">
    <inertial>
      <mass value="0.7"/>
      <origin rpy="0  0  0" xyz="-4.00000000e-05   8.11790000e-01   0.273561"/>
      <inertia ixx="0.003" ixy="0" ixz="0" iyy="0.00189" iyz="0" izz="0.00224"/>
    </inertial>
    <collision name="rrbot__collision">
      <origin rpy="0  0  0" xyz="-4.00000000e-05   8.11790000e-01   0.273561"/>
      <geometry>
        <box size="0.103506 0.172189 0.147122"/>
      </geometry>
    </collision>
    <visual name="rrbot__visual">
      <origin rpy="0  0  0" xyz="-4.00000000e-05   8.11790000e-01   0.273561"/>
      <geometry>
        <box size="0.103506 0.172189 0.147122"/>
      </geometry>
    </visual>
  </link>

  <link name="rrbot__link_0_0">
    <inertial>
      <mass value="0.04"/>
      <origin rpy="0  0  0" xyz="0  0  0"/>
      <inertia ixx="5.3e-06" ixy="0" ixz="0" iyy="1.2e-05" iyz="0" izz="1e-05"/>
    </inertial>
    <collision name="rrbot__collision">
      <origin rpy="0  0  0" xyz="0  0  0"/>
      <geometry>
        <box size="0.047498 0.023913 0.031645"/>
      </geometry>
    </collision>
    <visual name="rrbot__visual">
      <origin rpy="0  0  0" xyz="0  0  0"/>
      <geometry>
        <box size="0.047498 0.023913 0.031645"/>
      </geometry>
    </visual>
  </link>
  <link name="rrbot__link_0_0_clone">
    <inertial>
      <mass value="0.04"/>
      <origin rpy="0  0  0" xyz="0  0  0"/>
      <inertia ixx="5.3e-06" ixy="0" ixz="0" iyy="1.2e-05" iyz="0" izz="1e-05"/>
    </inertial>
    <collision name="rrbot__collision">
      <origin rpy="0  0  0" xyz="0  0  0"/>
      <geometry>
        <box size="0.047498 0.023913 0.031645"/>
      </geometry>
    </collision>
    <visual name="rrbot__visual_0">
      <origin rpy="0  0  0" xyz="0  0  0"/>
      <geometry>
        <box size="0.047498 0.023913 0.031645"/>
      </geometry>
      <material name="black"/>
    </visual>
  </link>
  <link name="rrbot__link_0_0_clone_0">
    <inertial>
      <mass value="0.04"/>
      <origin rpy="0  0  0" xyz="0  0  0"/>
      <inertia ixx="5.3e-06" ixy="0" ixz="0" iyy="1.2e-05" iyz="0" izz="1e-05"/>
    </inertial>
    <collision name="rrbot__collision">
      <origin rpy="0  0  0" xyz="0  0  0"/>
      <geometry>
        <box size="0.047498 0.023913 0.031645"/>
      </geometry>
    </collision>
    <visual name="rrbot__visual_0">
      <origin rpy="0  0  0" xyz="0  0  0"/>
      <geometry>
        <box size="0.047498 0.023913 0.031645"/>
      </geometry>
      <material name="black"/>
    </visual>
  </link>
  <link name="rrbot__link_0_0_clone_1">
    <inertial>
      <mass value="0.04"/>
      <origin rpy="0  0  0" xyz="0  0  0"/>
      <inertia ixx="5.3e-06" ixy="0" ixz="0" iyy="1.2e-05" iyz="0" izz="1e-05"/>
    </inertial>
    <collision name="rrbot__collision">
      <origin rpy="0  0  0" xyz="0  0  0"/>
      <geometry>
        <box size="0.047498 0.023913 0.031645"/>
      </geometry>
    </collision>
    <visual name="rrbot__visual_0">
      <origin rpy="0  0  0" xyz="0  0  0"/>
      <geometry>
        <box size="0.047498 0.023913 0.031645"/>
      </geometry>
      <material name="black"/>
    </visual>
  </link>
  <link name="rrbot__link_0_0_clone_clone">
    <inertial>
      <mass value="0.005"/>
      <origin rpy="0  0  0" xyz="0  0  0"/>
      <inertia ixx="6.6e-07" ixy="0" ixz="0" iyy="4.6e-07" iyz="0" izz="2.5e-07"/>
    </inertial>
    <collision name="rrbot__collision">
      <origin rpy="0  0  0" xyz="0  0  0"/>
      <geometry>
        <box size="0.00666 0.023913 0.031645"/>
      </geometry>
    </collision>
    <visual name="rrbot__visual_0">
      <origin rpy="0  0  0" xyz="0  0  0"/>
      <geometry>
        <box size="0.00666 0.023913 0.031645"/>
      </geometry>
      <material name="black"/>
    </visual>
  </link>
  <link name="rrbot__link_0_0_clone_clone_clone">
    <inertial>
      <mass value="0.005"/>
      <origin rpy="0  0  0" xyz="0  0  0"/>
      <inertia ixx="6.6e-07" ixy="0" ixz="0" iyy="4.6e-07" iyz="0" izz="2.5e-07"/>
    </inertial>
    <collision name="rrbot__collision">
      <origin rpy="0  0  0" xyz="0  0  0"/>
      <geometry>
        <box size="0.00666 0.023913 0.031645"/>
      </geometry>
    </collision>
    <visual name="rrbot__visual_0">
      <origin rpy="0  0  0" xyz="0  0  0"/>
      <geometry>
        <box size="0.00666 0.023913 0.031645"/>
      </geometry>
      <material name="black"/>
    </visual>
  </link>
  <link name="rrbot__link_0_0_clone_clone_clone_0">
    <inertial>
      <mass value="0.005"/>
      <origin rpy="0  0  0" xyz="0  0  0"/>
      <inertia ixx="6.6e-07" ixy="0" ixz="0" iyy="4.6e-07" iyz="0" izz="2.5e-07"/>
    </inertial>
    <collision name="rrbot__collision">
      <origin rpy="0  0  0" xyz="0  0  0"/>
      <geometry>
        <box size="0.00666 0.023913 0.031645"/>
      </geometry>
    </collision>
    <visual name="rrbot__visual_0">
      <origin rpy="0  0  0" xyz="0  0  0"/>
      <geometry>
        <box size="0.00666 0.023913 0.031645"/>
      </geometry>
      <material name="black"/>
    </visual>
  </link>
  <link name="rrbot__link_0_0_clone_clone_clone_0_clone">
    <inertial>
      <mass value="0.005"/>
      <origin rpy="0  0  0" xyz="0  0  0"/>
      <inertia ixx="6.6e-07" ixy="0" ixz="0" iyy="4.6e-07" iyz="0" izz="2.5e-07"/>
    </inertial>
    <collision name="rrbot__collision">
      <origin rpy="0  0  0" xyz="0  0  0"/>
      <geometry>
        <box size="0.00666 0.023913 0.031645"/>
      </geometry>
    </collision>
    <visual name="rrbot__visual_0">
      <origin rpy="0  0  0" xyz="0  0  0"/>
      <geometry>
        <box size="0.00666 0.023913 0.031645"/>
      </geometry>
      <material name="black"/>
    </visual>
  </link>
  <link name="rrbot__link_0_0_clone_clone_clone_1">
    <inertial>
      <mass value="0.005"/>
      <origin rpy="0  0  0" xyz="0  0  0"/>
      <inertia ixx="6.6e-07" ixy="0" ixz="0" iyy="4.6e-07" iyz="0" izz="2.5e-07"/>
    </inertial>
    <collision name="rrbot__collision">
      <origin rpy="0  0  0" xyz="0  0  0"/>
      <geometry>
        <box size="0.00666 0.023913 0.031645"/>
      </geometry>
    </collision>
    <visual name="rrbot__visual_0">
      <origin rpy="0  0  0" xyz="0  0  0"/>
      <geometry>
        <box size="0.00666 0.023913 0.031645"/>
      </geometry>
      <material name="black"/>
    </visual>
  </link>
  <link name="rrbot__link_0_0_clone_clone_clone_2">
    <inertial>
      <mass value="0.005"/>
      <origin rpy="0  0  0" xyz="0  0  0"/>
      <inertia ixx="6.6e-07" ixy="0" ixz="0" iyy="4.6e-07" iyz="0" izz="2.5e-07"/>
    </inertial>
    <collision name="rrbot__collision">
      <origin rpy="0  0  0" xyz="0  0  0"/>
      <geometry>
        <box size="0.00666 0.023913 0.031645"/>
      </geometry>
    </collision>
    <visual name="rrbot__visual_0">
      <origin rpy="0  0  0" xyz="0  0  0"/>
      <geometry>
        <box size="0.00666 0.023913 0.031645"/>
      </geometry>
      <material name="black"/>
    </visual>
  </link>
  <link name="rrbot__link_0_0_clone_clone_clone_3">
    <inertial>
      <mass value="0.005"/>
      <origin rpy="0  0  0" xyz="0  0  0"/>
      <inertia ixx="6.6e-07" ixy="0" ixz="0" iyy="4.6e-07" iyz="0" izz="2.5e-07"/>
    </inertial>
    <collision name="rrbot__collision">
      <origin rpy="0  0  0" xyz="0  0  0"/>
      <geometry>
        <box size="0.00666 0.023913 0.031645"/>
      </geometry>
    </collision>
    <visual name="rrbot__visual_0">
      <origin rpy="0  0  0" xyz="0  0  0"/>
      <geometry>
        <box size="0.00666 0.023913 0.031645"/>
      </geometry>
      <material name="black"/>
    </visual>
  </link>
  <link name="rrbot__link_0_0_clone_clone_clone_clone">
    <inertial>
      <mass value="0.005"/>
      <origin rpy="0  0  0" xyz="0  0  0"/>
      <inertia ixx="6.6e-07" ixy="0" ixz="0" iyy="4.6e-07" iyz="0" izz="2.5e-07"/>
    </inertial>
    <collision name="rrbot__collision">
      <origin rpy="0  0  0" xyz="0  0  0"/>
      <geometry>
        <box size="0.00666 0.023913 0.031645"/>
      </geometry>
    </collision>
    <visual name="rrbot__visual_0">
      <origin rpy="0  0  0" xyz="0  0  0"/>
      <geometry>
        <box size="0.00666 0.023913 0.031645"/>
      </geometry>
      <material name="black"/>
    </visual>
  </link>
  <link name="rrbot__link_0_clone">
    <inertial>
      <mass value="0.2"/>
      <origin rpy="0  0  0" xyz="0  0  0"/>
      <inertia ixx="0.00054" ixy="0" ixz="0" iyy="0.000684" iyz="0" izz="0.000476"/>
    </inertial>
    <collision name="rrbot__collision">
      <origin rpy="0  0  0" xyz="0  0  0"/>
      <geometry>
        <box size="0.13585 0.095615 0.147122"/>
      </geometry>
    </collision>
    <visual name="rrbot__visual">
      <origin rpy="0  0  0" xyz="0  0  0"/>
      <geometry>
        <box size="0.13585 0.095615 0.147122"/>
      </geometry>
      <material name="grey"/>
    </visual>
  </link>
  <link name="rrbot__link_0_clone_0">
    <inertial>
      <mass value="0.3"/>
      <origin rpy="0  0  0" xyz="0  0  0"/>
      <inertia ixx="0.0013" ixy="0" ixz="0" iyy="0.00081" iyz="0" izz="0.001"/>
    </inertial>
    <collision name="rrbot__collision">
      <origin rpy="0  0  0" xyz="0  0  0"/>
      <geometry>
        <box size="0.103506 0.172189 0.147122"/>
      </geometry>
    </collision>
    <visual name="rrbot__visual">
      <origin rpy="0  0  0" xyz="0  0  0"/>
      <geometry>
        <box size="0.103506 0.172189 0.147122"/>
      </geometry>
      <material name="grey"/>
    </visual>
  </link>
  <link name="rrbot__link_0_clone_1">
    <inertial>
      <mass value="0.2"/>
      <origin rpy="0  0  0" xyz="0  0  0"/>
      <inertia ixx="0.00086" ixy="0" ixz="0" iyy="0.00054" iyz="0" izz="0.00065"/>
    </inertial>
    <collision name="rrbot__collision">
      <origin rpy="0  0  0" xyz="0  0  0"/>
      <geometry>
        <box size="0.103506 0.172189 0.147122"/>
      </geometry>
    </collision>
    <visual name="rrbot__visual">
      <origin rpy="0  0  0" xyz="0  0  0"/>
      <geometry>
        <box size="0.103506 0.172189 0.147122"/>
      </geometry>
      <material name="grey"/>
    </visual>
  </link>
  <link name="rrbot__link_0_clone_2">
    <inertial>
      <mass value="0.2"/>
      <origin rpy="0  0  0" xyz="0  0  0"/>
      <inertia ixx="0.00086" ixy="0" ixz="0" iyy="0.00054" iyz="0" izz="0.00065"/>
    </inertial>
    <collision name="rrbot__collision">
      <origin rpy="0  0  0" xyz="0  0  0"/>
      <geometry>
        <box size="0.103506 0.172189 0.147122"/>
      </geometry>
    </collision>
    <visual name="rrbot__visual">
      <origin rpy="0  0  0" xyz="0  0  0"/>
      <geometry>
        <box size="0.103506 0.172189 0.147122"/>
      </geometry>
      <material name="grey"/>
    </visual>
  </link>
  <link name="rrbot__link_0_clone_3">
    <inertial>
      <mass value="0.15"/>
      <origin rpy="0  0  0" xyz="0  0  0"/>
      <inertia ixx="0.00064" ixy="0" ixz="0" iyy="0.00041" iyz="0" izz="0.00049"/>
    </inertial>
    <collision name="rrbot__collision">
      <origin rpy="0  0  0" xyz="0  0  0"/>
      <geometry>
        <box size="0.103506 0.172189 0.147122"/>
      </geometry>
    </collision>
    <visual name="rrbot__visual">
      <origin rpy="0  0  0" xyz="0  0  0"/>
      <geometry>
        <box size="0.103506 0.172189 0.147122"/>
      </geometry>
      <material name="grey"/>
    </visual>
  </link>
  <link name="rrbot__link_0_clone_4">
    <inertial>
      <mass value="0.15"/>
      <origin rpy="0  0  0" xyz="0  0  0"/>
      <inertia ixx="0.00064" ixy="0" ixz="0" iyy="0.00041" iyz="0" izz="0.00049"/>
    </inertial>
    <collision name="rrbot__collision">
      <origin rpy="0  0  0" xyz="0  0  0"/>
      <geometry>
        <box size="0.103506 0.172189 0.147122"/>
      </geometry>
    </collision>
    <visual name="rrbot__visual">
      <origin rpy="0  0  0" xyz="0  0  0"/>
      <geometry>
        <box size="0.103506 0.172189 0.147122"/>
      </geometry>
      <material name="grey"/>
    </visual>
  </link>
  <link name="rrbot__link_0_clone_5">
    <inertial>
      <mass value="0.15"/>
      <origin rpy="0  0  0" xyz="0  0  0"/>
      <inertia ixx="0.00064" ixy="0" ixz="0" iyy="0.00041" iyz="0" izz="0.00049"/>
    </inertial>
    <collision name="rrbot__collision">
      <origin rpy="0  0  0" xyz="0  0  0"/>
      <geometry>
        <box size="0.103506 0.172189 0.147122"/>
      </geometry>
    </collision>
    <visual name="rrbot__visual">
      <origin rpy="0  0  0" xyz="0  0  0"/>
      <geometry>
        <box size="0.103506 0.172189 0.147122"/>
      </geometry>
      <material name="grey"/>
    </visual>
  </link>
  <link name="rrbot__link_0_clone_6">
    <inertial>
      <mass value="0.01"/>
      <origin rpy="0  0  0" xyz="0  0  0"/>
      <inertia ixx="2.7e-06" ixy="0" ixz="0" iyy="5.8e-06" iyz="0" izz="3.5e-06"/>
    </inertial>
    <collision name="rrbot__collision">
      <origin rpy="0  0  0" xyz="0  0  0"/>
      <geometry>
        <box size="0.061873 0.013761 0.056246"/>
      </geometry>
    </collision>
    <visual name="rrbot__visual">
      <origin rpy="0  0  0" xyz="0  0  0"/>
      <geometry>
        <box size="0.061873 0.013761 0.056246"/>
      </geometry>
      <material name="grey"/>
    </visual>
  </link>
  <link name="rrbot__link_0_clone_6_clone">
    <inertial>
      <mass value="0.01"/>
      <origin rpy="0  0  0" xyz="0  0  0"/>
      <inertia ixx="2.7e-06" ixy="0" ixz="0" iyy="5.8e-06" iyz="0" izz="3.5e-06"/>
    </inertial>
    <collision name="rrbot__collision">
      <origin rpy="0  0  0" xyz="0  0  0"/>
      <geometry>
        <box size="0.061873 0.013761 0.056246"/>
      </geometry>
    </collision>
    <visual name="rrbot__visual">
      <origin rpy="0  0  0" xyz="0  0  0"/>
      <geometry>
        <box size="0.061873 0.013761 0.056246"/>
      </geometry>
      <material name="grey"/>
    </visual>
  </link>
  <link name="rrbot__link_0_clone_6_clone_0">
    <inertial>
      <mass value="0.01"/>
      <origin rpy="0  0  0" xyz="0  0  0"/>
      <inertia ixx="2.7e-06" ixy="0" ixz="0" iyy="5.8e-06" iyz="0" izz="3.5e-06"/>
    </inertial>
    <collision name="rrbot__collision">
      <origin rpy="0  0  0" xyz="0  0  0"/>
      <geometry>
        <box size="0.061873 0.013761 0.056246"/>
      </geometry>
    </collision>
    <visual name="rrbot__visual">
      <origin rpy="0  0  0" xyz="0  0  0"/>
      <geometry>
        <box size="0.061873 0.013761 0.056246"/>
      </geometry>
      <material name="grey"/>
    </visual>
  </link>
  <link name="rrbot__link_0_clone_6_clone_1">
    <inertial>
      <mass value="0.01"/>
      <origin rpy="0  0  0" xyz="0  0  0"/>
      <inertia ixx="2.7e-06" ixy="0" ixz="0" iyy="5.8e-06" iyz="0" izz="3.5e-06"/>
    </inertial>
    <collision name="rrbot__collision">
      <origin rpy="0  0  0" xyz="0  0  0"/>
      <geometry>
        <box size="0.061873 0.013761 0.056246"/>
      </geometry>
    </collision>
    <visual name="rrbot__visual">
      <origin rpy="0  0  0" xyz="0  0  0"/>
      <geometry>
        <box size="0.061873 0.013761 0.056246"/>
      </geometry>
      <material name="grey"/>
    </visual>
  </link>
  <link name="rrbot__link_0_clone_6_clone_2">
    <inertial>
      <mass value="0.01"/>
      <origin rpy="0  0  0" xyz="0  0  0"/>
      <inertia ixx="2.7e-06" ixy="0" ixz="0" iyy="5.8e-06" iyz="0" izz="3.5e-06"/>
    </inertial>
    <collision name="rrbot__collision">
      <origin rpy="0  0  0" xyz="0  0  0"/>
      <geometry>
        <box size="0.061873 0.013761 0.056246"/>
      </geometry>
    </collision>
    <visual name="rrbot__visual">
      <origin rpy="0  0  0" xyz="0  0  0"/>
      <geometry>
        <box size="0.061873 0.013761 0.056246"/>
      </geometry>
      <material name="grey"/>
    </visual>
  </link>
  <link name="rrbot__link_0_clone_6_clone_3">
    <inertial>
      <mass value="0.01"/>
      <origin rpy="0  0  0" xyz="0  0  0"/>
      <inertia ixx="2.7e-06" ixy="0" ixz="0" iyy="5.8e-06" iyz="0" izz="3.5e-06"/>
    </inertial>
    <collision name="rrbot__collision">
      <origin rpy="0  0  0" xyz="0  0  0"/>
      <geometry>
        <box size="0.061873 0.013761 0.056246"/>
      </geometry>
    </collision>
    <visual name="rrbot__visual">
      <origin rpy="0  0  0" xyz="0  0  0"/>
      <geometry>
        <box size="0.061873 0.013761 0.056246"/>
      </geometry>
      <material name="grey"/>
    </visual>
  </link>
  <link name="rrbot__link_0_clone_6_clone_4">
    <inertial>
      <mass value="0.01"/>
      <origin rpy="0  0  0" xyz="0  0  0"/>
      <inertia ixx="2.7e-06" ixy="0" ixz="0" iyy="5.8e-06" iyz="0" izz="3.5e-06"/>
    </inertial>
    <collision name="rrbot__collision">
      <origin rpy="0  0  0" xyz="0  0  0"/>
      <geometry>
        <box size="0.061873 0.013761 0.056246"/>
      </geometry>
    </collision>
    <visual name="rrbot__visual">
      <origin rpy="0  0  0" xyz="0  0  0"/>
      <geometry>
        <box size="0.061873 0.013761 0.056246"/>
      </geometry>
      <material name="grey"/>
    </visual>
  </link>
  <link name="rrbot__link_0_clone_6_clone_5">
    <inertial>
      <mass value="0.01"/>
      <origin rpy="0  0  0" xyz="0  0  0"/>
      <inertia ixx="2.7e-06" ixy="0" ixz="0" iyy="5.8e-06" iyz="0" izz="3.5e-06"/>
    </inertial>
    <collision name="rrbot__collision">
      <origin rpy="0  0  0" xyz="0  0  0"/>
      <geometry>
        <box size="0.061873 0.013761 0.056246"/>
      </geometry>
    </collision>
    <visual name="rrbot__visual">
      <origin rpy="0  0  0" xyz="0  0  0"/>
      <geometry>
        <box size="0.061873 0.013761 0.056246"/>
      </geometry>
      <material name="grey"/>
    </visual>
  </link>
  <link name="rrbot__link_0_clone_6_clone_6">
    <inertial>
      <mass value="0.01"/>
      <origin rpy="0  0  0" xyz="0  0  0"/>
      <inertia ixx="2.7e-06" ixy="0" ixz="0" iyy="5.8e-06" iyz="0" izz="3.5e-06"/>
    </inertial>
    <collision name="rrbot__collision">
      <origin rpy="0  0  0" xyz="0  0  0"/>
      <geometry>
        <box size="0.061873 0.013761 0.056246"/>
      </geometry>
    </collision>
    <visual name="rrbot__visual">
      <origin rpy="0  0  0" xyz="0  0  0"/>
      <geometry>
        <box size="0.061873 0.013761 0.056246"/>
      </geometry>
      <material name="grey"/>
    </visual>
  </link>
  <link name="rrbot__link_0_clone_6_clone_7">
    <inertial>
      <mass value="0.01"/>
      <origin rpy="0  0  0" xyz="0  0  0"/>
      <inertia ixx="2.7e-06" ixy="0" ixz="0" iyy="5.8e-06" iyz="0" izz="3.5e-06"/>
    </inertial>
    <collision name="rrbot__collision">
      <origin rpy="0  0  0" xyz="0  0  0"/>
      <geometry>
        <box size="0.061873 0.013761 0.056246"/>
      </geometry>
    </collision>
    <visual name="rrbot__visual">
      <origin rpy="0  0  0" xyz="0  0  0"/>
      <geometry>
        <box size="0.061873 0.013761 0.056246"/>
      </geometry>
      <material name="grey"/>
    </visual>
  </link>
  <link name="rrbot__link_0_clone_6_clone_8">
    <inertial>
      <mass value="0.01"/>
      <origin rpy="0  0  0" xyz="0  0  0"/>
      <inertia ixx="2.7e-06" ixy="0" ixz="0" iyy="5.8e-06" iyz="0" izz="3.5e-06"/>
    </inertial>
    <collision name="rrbot__collision">
      <origin rpy="0  0  0" xyz="0  0  0"/>
      <geometry>
        <box size="0.061873 0.013761 0.056246"/>
      </geometry>
    </collision>
    <visual name="rrbot__visual">
      <origin rpy="0  0  0" xyz="0  0  0"/>
      <geometry>
        <box size="0.061873 0.013761 0.056246"/>
      </geometry>
      <material name="grey"/>
    </visual>
  </link>
  <link name="rrbot__link_0_clone_6_clone_9">
    <inertial>
      <mass value="0.01"/>
      <origin rpy="0  0  0" xyz="0  0  0"/>
      <inertia ixx="2.7e-06" ixy="0" ixz="0" iyy="5.8e-06" iyz="0" izz="3.5e-06"/>
    </inertial>
    <collision name="rrbot__collision">
      <origin rpy="0  0  0" xyz="0  0  0"/>
      <geometry>
        <box size="0.061873 0.013761 0.056246"/>
      </geometry>
    </collision>
    <visual name="rrbot__visual">
      <origin rpy="0  0  0" xyz="0  0  0"/>
      <geometry>
        <box size="0.061873 0.013761 0.056246"/>
      </geometry>
      <material name="grey"/>
    </visual>
  </link>
  <link name="rrbot__link_0_clone_clone">
    <inertial>
      <mass value="0.1"/>
      <origin rpy="0  0  0" xyz="0  0  0"/>
      <inertia ixx="0.00027" ixy="0" ixz="0" iyy="0.000342" iyz="0" izz="0.000238"/>
    </inertial>
    <collision name="rrbot__collision">
      <origin rpy="0  0  0" xyz="0  0  0"/>
      <geometry>
        <box size="0.13585 0.095615 0.147122"/>
      </geometry>
    </collision>
    <visual name="rrbot__visual">
      <origin rpy="0  0  0" xyz="0  0  0"/>
      <geometry>
        <box size="0.13585 0.095615 0.147122"/>
      </geometry>
      <material name="grey"/>
    </visual>
  </link>
  <link name="rrbot__link_2_clone">
    <inertial>
      <mass value="0.02"/>
      <origin rpy="0  0  0" xyz="0  0  0"/>
      <inertia ixx="1.7e-06" ixy="0" ixz="0" iyy="1.7e-06" iyz="0" izz="1.7e-06"/>
    </inertial>
    <collision name="rrbot__collision">
      <origin rpy="0  0  0" xyz="0  0  0"/>
      <geometry>
        <cylinder length="0.018" radius="0.0217706"/>
      </geometry>
    </collision>
    <visual name="rrbot__visual">
      <origin rpy="0  0  0" xyz="0  0  0"/>
      <geometry>
        <cylinder length="0.018" radius="0.0217706"/>
      </geometry>
      <material name="black"/>
    </visual>
  </link>
  <link name="rrbot__link_2_clone_1">
    <inertial>
      <mass value="0.03"/>
      <origin rpy="0  0  0" xyz="0  0  0"/>
      <inertia ixx="0.0001" ixy="0" ixz="0" iyy="0.0001" iyz="0" izz="0.0001"/>
    </inertial>
    <collision name="rrbot__collision">
      <origin rpy="0  0  0" xyz="0  0  0"/>
      <geometry>
        <cylinder length="0.092439" radius="0.013308"/>
      </geometry>
    </collision>
    <visual name="rrbot__visual">
      <origin rpy="0  0  0" xyz="0  0  0"/>
      <geometry>
        <cylinder length="0.093809" radius="0.013308"/>
      </geometry>
      <material name="black"/>
    </visual>
  </link>
  <link name="rrbot__link_2_clone_1_clone">
    <inertial>
      <mass value="0.03"/>
      <origin rpy="0  0  0" xyz="0  0  0"/>
      <inertia ixx="0.0001" ixy="0" ixz="0" iyy="0.0001" iyz="0" izz="0.0001"/>
    </inertial>
    <collision name="rrbot__collision">
      <origin rpy="0  0  0" xyz="0  0  0"/>
      <geometry>
        <cylinder length="0.092439" radius="0.013308"/>
      </geometry>
    </collision>
    <visual name="rrbot__visual">
      <origin rpy="0  0  0" xyz="0  0  0"/>
      <geometry>
        <cylinder length="0.093809" radius="0.013308"/>
      </geometry>
      <material name="black"/>
    </visual>
  </link>
  <link name="rrbot__link_2_clone_1_clone_0">
    <inertial>
      <mass value="0.03"/>
      <origin rpy="0  0  0" xyz="0  0  0"/>
      <inertia ixx="0.0001" ixy="0" ixz="0" iyy="0.0001" iyz="0" izz="0.0001"/>
    </inertial>
    <collision name="rrbot__collision">
      <origin rpy="0  0  0" xyz="0  0  0"/>
      <geometry>
        <cylinder length="0.092439" radius="0.013308"/>
      </geometry>
    </collision>
    <visual name="rrbot__visual">
      <origin rpy="0  0  0" xyz="0  0  0"/>
      <geometry>
        <cylinder length="0.093809" radius="0.013308"/>
      </geometry>
      <material name="black"/>
    </visual>
  </link>
  <link name="rrbot__link_2_clone_1_clone_0_clone">
    <inertial>
      <mass value="0.03"/>
      <origin rpy="0  0  0" xyz="0  0  0"/>
      <inertia ixx="0.0001" ixy="0" ixz="0" iyy="0.0001" iyz="0" izz="0.0001"/>
    </inertial>
    <collision name="rrbot__collision">
      <origin rpy="0  0  0" xyz="0  0  0"/>
      <geometry>
        <cylinder length="0.092439" radius="0.013308"/>
      </geometry>
    </collision>
    <visual name="rrbot__visual">
      <origin rpy="0  0  0" xyz="0  0  0"/>
      <geometry>
        <cylinder length="0.093809" radius="0.013308"/>
      </geometry>
      <material name="black"/>
    </visual>
  </link>
  <link name="rrbot__link_2_clone_clone">
    <inertial>
      <mass value="0.02"/>
      <origin rpy="0  0  0" xyz="0  0  0"/>
      <inertia ixx="1.7e-06" ixy="0" ixz="0" iyy="1.7e-06" iyz="0" izz="1.7e-06"/>
    </inertial>
    <collision name="rrbot__collision">
      <origin rpy="0  0  0" xyz="0  0  0"/>
      <geometry>
        <cylinder length="0.018" radius="0.0217706"/>
      </geometry>
    </collision>
    <visual name="rrbot__visual">
      <origin rpy="0  0  0" xyz="0  0  0"/>
      <geometry>
        <cylinder length="0.018" radius="0.0217706"/>
      </geometry>
      <material name="black"/>
    </visual>
  </link>
  <link name="rrbot__link_2_clone_clone_0">
    <inertial>
      <mass value="0.02"/>
      <origin rpy="0  0  0" xyz="0  0  0"/>
      <inertia ixx="1.7e-06" ixy="0" ixz="0" iyy="1.7e-06" iyz="0" izz="1.7e-06"/>
    </inertial>
    <collision name="rrbot__collision">
      <origin rpy="0  0  0" xyz="0  0  0"/>
      <geometry>
        <cylinder length="0.018" radius="0.0217706"/>
      </geometry>
    </collision>
    <visual name="rrbot__visual">
      <origin rpy="0  0  0" xyz="0  0  0"/>
      <geometry>
        <cylinder length="0.018" radius="0.0217706"/>
      </geometry>
      <material name="black"/>
    </visual>
  </link>
  <link name="rrbot__link_2_clone_clone_0_clone">
    <inertial>
      <mass value="0.02"/>
      <origin rpy="0  0  0" xyz="0  0  0"/>
      <inertia ixx="1.7e-06" ixy="0" ixz="0" iyy="1.7e-06" iyz="0" izz="1.7e-06"/>
    </inertial>
    <collision name="rrbot__collision">
      <origin rpy="0  0  0" xyz="0  0  0"/>
      <geometry>
        <cylinder length="0.018" radius="0.0217706"/>
      </geometry>
    </collision>
    <visual name="rrbot__visual">
      <origin rpy="0  0  0" xyz="0  0  0"/>
      <geometry>
        <cylinder length="0.018" radius="0.0217706"/>
      </geometry>
      <material name="black"/>
    </visual>
  </link>
  <link name="rrbot__link_3">
    <inertial>
      <mass value="1.433e-05"/>
      <origin rpy="0  0  0" xyz="0  0  0"/>
      <inertia ixx="0" ixy="0" ixz="0" iyy="0" iyz="0" izz="0"/>
    </inertial>
    <collision name="rrbot__collision">
      <origin rpy="0  0  0" xyz="0  0  0"/>
      <geometry>
        <sphere radius="0.012144"/>
      </geometry>
    </collision>
    <visual name="rrbot__visual">
      <origin rpy="0  0  0" xyz="0  0  0"/>
      <geometry>
        <sphere radius="0.0121437"/>
      </geometry>
      <material name="black"/>
    </visual>
  </link>
  <link name="rrbot__link_3_clone">
    <inertial>
      <mass value="1.433e-05"/>
      <origin rpy="0  0  0" xyz="0  0  0"/>
      <inertia ixx="0" ixy="0" ixz="0" iyy="0" iyz="0" izz="0"/>
    </inertial>
    <collision name="rrbot__collision">
      <origin rpy="0  0  0" xyz="0  0  0"/>
      <geometry>
        <sphere radius="0.012144"/>
      </geometry>
    </collision>
    <visual name="rrbot__visual">
      <origin rpy="0  0  0" xyz="0  0  0"/>
      <geometry>
        <sphere radius="0.0121437"/>
      </geometry>
      <material name="black">
    	<color rgba="0.0 0.0 0.0 1.0"/>
      </material>
    </visual>
  </link>


  <transmission name="tran_limb1">
    <type>transmission_interface/SimpleTransmission</type>
    <joint name="rrbot__limb_joint_1">
      <hardwareInterface>hardware_interface/EffortJointInterface</hardwareInterface>
    </joint>
    <actuator name="rrbot__limb_joint_1">
      <hardwareInterface>hardware_interface/EffortJointInterface</hardwareInterface>
      <mechanicalReduction>100</mechanicalReduction>
    </actuator>
 </transmission>

  <transmission name="tran_limb_2">
    <type>transmission_interface/SimpleTransmission</type>
    <joint name="rrbot__limb_joint_2">
      <hardwareInterface>hardware_interface/EffortJointInterface</hardwareInterface>
    </joint>
    <actuator name="rrbot__limb_joint_2">
      <hardwareInterface>hardware_interface/EffortJointInterface</hardwareInterface>
      <mechanicalReduction>100</mechanicalReduction>
    </actuator>
 </transmission>

  <transmission name="tran_limb_3">
    <type>transmission_interface/SimpleTransmission</type>
    <joint name="rrbot__limb_joint_3">
      <hardwareInterface>hardware_interface/EffortJointInterface</hardwareInterface>
    </joint>
    <actuator name="rrbot__limb_joint_3">
      <hardwareInterface>hardware_interface/EffortJointInterface</hardwareInterface>
      <mechanicalReduction>100</mechanicalReduction>
    </actuator>
 </transmission>

  <transmission name="tran_limb_4">
    <type>transmission_interface/SimpleTransmission</type>
    <joint name="rrbot__limb_joint_4">
      <hardwareInterface>hardware_interface/EffortJointInterface</hardwareInterface>
    </joint>
    <actuator name="rrbot__limb_joint_4">
      <hardwareInterface>hardware_interface/EffortJointInterface</hardwareInterface>
      <mechanicalReduction>100</mechanicalReduction>
    </actuator>
 </transmission>

  <transmission name="tran_body_1">
    <type>transmission_interface/SimpleTransmission</type>
    <joint name="rrbot__body_joint_1">
      <hardwareInterface>hardware_interface/EffortJointInterface</hardwareInterface>
    </joint>
    <actuator name="rrbot__body_joint_1">
      <hardwareInterface>hardware_interface/EffortJointInterface</hardwareInterface>
      <mechanicalReduction>1</mechanicalReduction>
    </actuator>
 </transmission>

  <transmission name="tran_body_2">
    <type>transmission_interface/SimpleTransmission</type>
    <joint name="rrbot__body_joint_2">
      <hardwareInterface>hardware_interface/EffortJointInterface</hardwareInterface>
    </joint>
    <actuator name="rrbot__body_joint_2">
      <hardwareInterface>hardware_interface/EffortJointInterface</hardwareInterface>
      <mechanicalReduction>1</mechanicalReduction>
    </actuator>
 </transmission>

  <transmission name="tran_body_3">
    <type>transmission_interface/SimpleTransmission</type>
    <joint name="rrbot__body_joint_3">
      <hardwareInterface>hardware_interface/EffortJointInterface</hardwareInterface>
    </joint>
    <actuator name="rrbot__body_joint_3">
      <hardwareInterface>hardware_interface/EffortJointInterface</hardwareInterface>
      <mechanicalReduction>1</mechanicalReduction>
    </actuator>
 </transmission>

  <transmission name="tran_body_4">
    <type>transmission_interface/SimpleTransmission</type>
    <joint name="rrbot__body_joint_4">
      <hardwareInterface>hardware_interface/EffortJointInterface</hardwareInterface>
    </joint>
    <actuator name="rrbot__body_joint_4">
      <hardwareInterface>hardware_interface/EffortJointInterface</hardwareInterface>
      <mechanicalReduction>1</mechanicalReduction>
    </actuator>
 </transmission>

  <transmission name="tran_body_5">
    <type>transmission_interface/SimpleTransmission</type>
    <joint name="rrbot__body_joint_5">
      <hardwareInterface>hardware_interface/EffortJointInterface</hardwareInterface>
    </joint>
    <actuator name="rrbot__body_joint_5">
      <hardwareInterface>hardware_interface/EffortJointInterface</hardwareInterface>
      <mechanicalReduction>1</mechanicalReduction>
    </actuator>
 </transmission>

  <transmission name="tran_body_6">
    <type>transmission_interface/SimpleTransmission</type>
    <joint name="rrbot__body_joint_6">
      <hardwareInterface>hardware_interface/EffortJointInterface</hardwareInterface>
    </joint>
    <actuator name="rrbot__body_joint_6">
      <hardwareInterface>hardware_interface/EffortJointInterface</hardwareInterface>
      <mechanicalReduction>1</mechanicalReduction>
    </actuator>
 </transmission>

</robot>
